Workbook

Sheet MP
B2: COPPER PRICE FORMULA | F2: PERIOD | I2: ALUMINIUM PRICE FORMULA | M2: PERIOD | P2: SILVER BASE PRICE | S2: PERIOD
B3: 9645.7 | D3: lme $/tonn | F3: AVG AUG 2025 | I3: 2593.8 | K3: lme $/tonn | M3: =F3 -> AVG AUG 2025 | P3: 1103.73 | Q3: Ag €/Kg | S3: =F3 -> AVG AUG 2025
B4: 340 | D4: prime $/tonn | I4: 0 | K4: prime $/tonn
B5: =((B3+B4)*(1+C5)) -> 10385.128 | C5: 0.04 | D5: Copper financial (4%) | I5: =(((I3+I4)*(1+J5))) -> 2593.8 | J5: 0 | K5: Alluminium financial
B6: =B5*(1+C6) -> 11008.236 | C6: 0.06 | D6: Management copper (6%) | I6: =I5*(1+J6) -> 2593.8 | J6: 0 | K6: Management alluminium
B7: 1.1631 | D7: change $/€ | I7: =B7 -> 1.1631 | K7: change $/€
B8: =IF(OR(B7=0,B7=""),0,(B6/B7)/1000) -> 9.4645651 | D8: Cu €/kg | I8: =IF(OR(I7=0,I7=""),0,I6/I7/1000) -> 2.2300748 | K8: Al €/kg

Sheet OFFER
B2: YOUR COMPANY NAME
B4: Customer
B5: Your request
B6: Offer. Nr.
B7: Offer Date
B8: Rev.
A10: GENERAL INFORMATION | I10: RAW MATERIAL | Q10: MACHINING | S10: SILVERING | V10: ADDITIONAL OPERATIONS | Z10: PACk & TRANSPORT | AB10: Price | AC10: TOOLING | AD10: DELIVERY
A11: Rif | B11: Document reference | C11: Document Title | D11: Drawing | E11: Rev. | F11: q.ty x year | G11: Prod. Batch | H11: Delivery Batch | I11: Brut Weight Kg/pc. | J11: Net Weight Kg/pc. | K11: Scrap Weight Kg/pc. | L11: Type | M11: Description | N11: Base Price €/Kg | O11: Transf. Price €/Kg | P11: Cost €/pc. | Q11: Setup €/pc. | R11: Machining €/pc. | S11: Silver Weight g/pc. | T11: Silver Cost €/pc. | U11: Silvering Operation €/pc. | V11: Description | W11: Activity €/pc. | X11: Description | Y11: Activity €/pc. | Z11: packaging €/pc. | AA11: transport €/pc | AB11: €/pc. | AC11: PARTECIPATION COST | AD11: First date | AE11: Last date
A12: 1 | AB12: =SUM(P12:R12)+SUM(T12:U12)+W12+Y12+Z12+AA12 -> 0
A13: 2 | AB13: =SUM(P13:R13)+SUM(T13:U13)+W13+Y13+Z13+AA13 -> 0
A14: 3 | AB14: =SUM(P14:R14)+SUM(T14:U14)+W14+Y14+Z14+AA14 -> 0
A15: 4
A16: 5
A17: 6
A18: 7
A19: 8
A20: 9
A21: 10
B23: DELIVERY TIME | C23: 70/80 working days minimum
B24: DELIVERY | C24: DAP - EX WORKS
B25: PAYMENT | C25: usual
B26: PACKAGING | C26: carton box
B27: PRICES | C27: will be updated with the LME raw material price
B28: VALIDITY

Sheet SC1
B1: OFFER | G1: Nr. | H1: 01/25 | I1: Date: | J1: 44599 | K1: Rev.: | L1: 0
B2: Customer: | C2: SCHNEIDER | F2: Your request: | H2: 1234 / 25
B3: Doc. reference: | C3: AK00002433757 | F3: Description: | H3: Copper bar
B4: Drawing: | C4: AK00002433757 | F4: Rev.: | G4: A1 | H4: Quantity x year: | J4: 14 | K4: Pr.Batch: | L4: 14
B5: First delivery date: | C5: 45803 | E5: Last delivery date: | G5: 45950 | H5: Delivery Batch: | J5: 14
A7: CDC | B7: Tooling (Una tantum) | C7: Q.ty | D7: Cost (€) | E7: Total (€) | F7: % Ric | G7: Price (€) | N7: Note
A8: TOOL | B8: Attrezzo di piega | C8: 1 | D8: 1500 | E8: =C8*D8 -> 1500 | F8: 1.1 | G8: =E8*F8 -> 1650 | N8: Realizzazato internamente
A9: TOOL | B9: Attrezzo lav mec | C9: 2 | D9: 600 | E9: =C9*D9 -> 1200 | F9: 1.1 | G9: =E9*F9 -> 1320 | N9: Beretta
A10: TOOL | B10: Test di campionatura | C10: 1 | D10: 50 | E10: =C10*D10 -> 50 | F10: 1.1 | G10: =E10*F10 -> 55
A11: TOOL | E11: =C11*D11 -> 0 | F11: 1.1 | G11: =E11*F11 -> 0
A12: TOOL | E12: =C12*D12 -> 0 | F12: 1.1 | G12: =E12*F12 -> 0
B13: Total | E13: =SUM(E8:E12) -> 2750 | G13: =SUM(G8:G12) -> 3025
A15: CDC | B15: Components | C15: Q.ty | D15: Cost (€) | E15: Total Cost (€) | F15: % Ric | G15: Price (€)
A16: COMP | B16: Guaina | C16: 1 | D16: 0.5 | E16: =C16*D16 -> 0.5 | F16: 1.2 | G16: =E16*F16 -> 0.6
A17: COMP | B17: Rivetti | C17: 1 | D17: 1 | E17: =C17*D17 -> 1 | F17: 1.2 | G17: =E17*F17 -> 1.2
A18: COMP | B18: Dadi | C18: 1 | D18: 3 | E18: =C18*D18 -> 3 | F18: 1.2 | G18: =E18*F18 -> 3.6
A19: COMP | B19: bulloni e tap pad INOX | C19: 1 | D19: 4 | E19: =C19*D19 -> 4 | F19: 1.3 | G19: =E19*F19 -> 5.2
A20: COMP | E20: =C20*D20 -> 0 | F20: 1.2 | G20: =E20*F20 -> 0
B21: Total | E21: =SUM(E16:E20) -> 8.5 | G21: =SUM(G16:G20) -> 10.6
A23: CDC | B23: Raw material | C23: Brut W. (Kg/pc) | D23: Net W. (Kg/pc) | E23: Scrap W. (Kg/pc) | F23: % Screp Value | G23: Transf. Price (€/Kg) | H23: Material Cost (€/pc) | I23: % Ric | J23: Price (€) | K23: LME ($/ton) | L23: Change (€/$) | M23: Material Cost (€/kg)
A24: CU | B24: LAM. CU ETP 1000x2000x3 H065 | C24: 0.11 | D24: 0.085 | E24: =C24-D24 -> 0.025 | F24: 0.7 | G24: 4.53 | H24: =IF($A24>0,(G24+M24)*C24-(K24/1000/L24*E24*F24),"") -> 1.394273 | I24: 1 | J24: =IF($A24>0,H24*I24,"") -> 1.394273 | K24: =IF($A24="CU",MP!$B$3,IF($A24="AL",MP!$I$3,"")) -> 9645.7 | L24: =IF($A24="CU",MP!$B$7,IF($A24="AL",MP!$I$7,"")) -> 1.1631 | M24: =IF($A24="CU",MP!$B$8,IF($A24="AL",MP!$I$8,"")) -> 9.4645651 | N24: Note mp
B25: Total | C25: =SUM(C24:C24) -> 0.11 | D25: =SUM(D24:D24) -> 0.085 | H25: =SUM(H24:H24) -> 1.394273 | J25: =SUM(J24:J24) -> 1.394273
A27: Fase | B27: Machining & Additional Operations | C27: Type | D27: Int/Ext | E27: Center | F27: Cost (€/ora - €/pz) | G27: T. Setup (min) | H27: T. Prod (sec) | I27: Setup cost (€) | J27: Prod. cost (€) | K27: % Ric | L27: Setup Price | M27: Prod Price
A28: 1 | B28: Progettazione | C28: MACH | D28: I | E28: PRG | F28: 48 | G28: 30 | H28: 0 | I28: =IF(OR($L$4=0,$L$4=""),0,G28/60/$L$4*F28) -> 1.7142857 | J28: =IF(D28="I",F28/3600*H28,F28) -> 0 | K28: 1 | L28: =I28*K28 -> 1.7142857 | M28: =IF(C28="ADD",(J28 + I28)*K28,J28*K28) -> 0
A29: 10 | B29: Taglio Laser | C29: MACH | D29: I | E29: TL | F29: 150 | G29: 0 | H29: 20 | J29: =IF(D29="I",F29/3600*H29,F29) -> 0.83333333 | K29: 1 | L29: =I29*K29 -> 0 | M29: =IF(C29="ADD",(J29 + I29)*K29,J29*K29) -> 0.83333333
A30: 20 | B30: Piega | C30: MACH | D30: I | E30: PIE | F30: 70 | G30: 15 | H30: 30 | I30: =IF(OR($L$4=0,$L$4=""),0,G30/60/$L$4*F30) -> 1.25 | J30: =IF(D30="I",F30/3600*H30,F30) -> 0.58333333 | K30: 1 | L30: =I30*K30 -> 1.25 | M30: =IF(C30="ADD",(J30 + I30)*K30,J30*K30) -> 0.58333333
A31: 30 | B31: Satinatura | C31: MACH | D31: I | E31: SAT | F31: 70 | G31: 15 | H31: 30 | I31: =IF(OR($L$4=0,$L$4=""),0,G31/60/$L$4*F31) -> 1.25 | J31: =IF(D31="I",F31/3600*H31,F31) -> 0.58333333 | K31: 1 | L31: =I31*K31 -> 1.25 | M31: =IF(C31="ADD",(J31 + I31)*K31,J31*K31) -> 0.58333333
A32: 40 | B32: Raggiatura Spigolo | C32: MACH | D32: I | E32: LAV | F32: 70 | G32: 0 | H32: 180 | I32: =IF(OR($L$4=0,$L$4=""),0,G32/60/$L$4*F32) -> 0 | J32: =IF(D32="I",F32/3600*H32,F32) -> 3.5 | K32: 1 | L32: =I32*K32 -> 0 | M32: =IF(C32="ADD",(J32 + I32)*K32,J32*K32) -> 3.5
A33: 60 | B33: Insulation | C33: MACH | D33: I | E33: ISO | F33: 70 | G33: 0 | H33: 300 | I33: =IF(OR($L$4=0,$L$4=""),0,G33/60/$L$4*F33) -> 0 | J33: =IF(D33="I",F33/3600*H33,F33) -> 5.8333333 | K33: 1.2 | L33: =I33*K33 -> 0 | M33: =IF(C33="ADD",(J33 + I33)*K33,J33*K33) -> 7
A34: 70 | B34: tinning 15µ | C34: ADD | D34: E | E34: TIN | F34: 1.1 | G34: 0 | H34: 0 | I34: =IF(OR($L$4=0,$L$4=""),0,G34/60/$L$4*F34) -> 0 | J34: =IF(D34="I",F34/3600*H34,F34) -> 1.1 | K34: 1.2 | L34: =I34*K34 -> 0 | M34: =IF(C34="ADD",(J34 + I34)*K34,J34*K34) -> 1.32
A35: 80 | B35: Controllo finale | C35: MACH | D35: I | F35: 70 | G35: 0 | H35: 20 | I35: =IF(OR($L$4=0,$L$4=""),0,G35/60/$L$4*F35) -> 0 | J35: =IF(D35="I",F35/3600*H35,F35) -> 0.38888889 | K35: 1 | L35: =I35*K35 -> 0 | M35: =IF(C35="ADD",(J35 + I35)*K35,J35*K35) -> 0.38888889
A36: 90 | C36: MACH | D36: I | I36: =IF(OR($L$4=0,$L$4=""),0,G36/60/$L$4*F36) -> 0 | K36: 1 | L36: =I36*K36 -> 0 | M36: =IF(C36="ADD",(J36 + I36)*K36,J36*K36) -> 0
A37: 100 | C37: MACH | D37: I | I37: =IF(OR($L$4=0,$L$4=""),0,G37/60/$L$4*F37) -> 0 | J37: =IF(D37="I",F37/3600*H37,F37) -> 0 | K37: 1 | L37: =I37*K37 -> 0 | M37: =IF(C37="ADD",(J37 + I37)*K37,J37*K37) -> 0
B38: Total Machining | L38: =SUMIF(C28:C37,"MACH",L28:L37) -> 4.2142857 | M38: =SUMIF(C28:C37,"MACH",M28:M37) -> 12.888889
B39: Total Additional Operations | M39: =SUMIF(C28:C37,"ADD",M28:M37) -> 1.32
A41: Fase | B41: Treatments | C41: Type | D41: Int/Ext | E41: Centro | G41: Oper. Cost (€/pc) | H41: % Oper Ric | I41: Oper. Price (€) | J41: Q.ty Ag (gr) | K41: Silver cost (€) | L41: % Silver Ric | M41: Silver Price (€)
A42: 50 | B42: Argentatura | C42: ARG | D42: E | E42: Arg | G42: 3 | H42: 1.3 | I42: =G42*H42 -> 3.9 | J42: 10 | K42: =J42*MP!P3/1000 -> 11.0373 | L42: 1.1 | M42: =K42*L42 -> 12.14103
B43: Total | I43: =I42 -> 3.9 | M43: =M42 -> 12.14103
A45: CDC | B45: Other | C45: Q.ty | D45: Unit Cost (€) | E45: Total cost (€) | G45: % Ric | H45: Price (€)
A46: TRAS | B46: Transport costs | C46: =D25 -> 0.085 | D46: 0.7 | E46: =C46*D46 -> 0.0595 | G46: 1 | H46: =E46*G46 -> 0.0595
...

Sheet SC2
B1: OFFER | G1: Nr. | H1: 01/25 | I1: Date: | J1: 44599 | K1: Rev.: | L1: 0
B2: Customer: | C2: SCHNEIDER | F2: Your request: | H2: 1234 / 25
B3: Doc. reference: | C3: AK0000584999 | F3: Description: | H3: Copper bar model 2
B4: Drawing: | C4: AK0000584999 | F4: Rev.: | G4: A2 | H4: Quantity x year: | J4: 15 | K4: Pr.Batch: | L4: 15
B5: First delivery date: | C5: 45803 | E5: Last delivery date: | G5: 45950 | H5: Delivery Batch: | J5: 15
A7: CDC | B7: Tooling (Una tantum) | C7: Q.ty | D7: Cost (€) | E7: Total (€) | F7: % Ric | G7: Price (€) | N7: Note
A8: TOOL | B8: Attrezzo di piega | C8: 2 | D8: 1500 | E8: =C8*D8 -> 3000 | F8: 1.1 | G8: =E8*F8 -> 3300 | N8: Realizzazato internamente
A9: TOOL | B9: Attrezzo lav mec | C9: 2 | D9: 600 | E9: =C9*D9 -> 1200 | F9: 1.1 | G9: =E9*F9 -> 1320 | N9: Beretta
A10: TOOL | B10: Test di campionatura | C10: 2 | D10: 50 | E10: =C10*D10 -> 100 | F10: 1.1 | G10: =E10*F10 -> 110
A11: TOOL | E11: =C11*D11 -> 0 | F11: 1.1 | G11: =E11*F11 -> 0
A12: TOOL | E12: =C12*D12 -> 0 | F12: 1.1 | G12: =E12*F12 -> 0
B13: Total | E13: =SUM(E8:E12) -> 4300 | G13: =SUM(G8:G12) -> 4730
A15: CDC | B15: Components | C15: Q.ty | D15: Cost (€) | E15: Total Cost (€) | F15: % Ric | G15: Price (€)
A16: COMP | B16: Guaina | C16: 2 | D16: 0.5 | E16: =C16*D16 -> 1 | F16: 1.2 | G16: =E16*F16 -> 1.2
A17: COMP | B17: Rivetti | C17: 2 | D17: 1 | E17: =C17*D17 -> 2 | F17: 1.2 | G17: =E17*F17 -> 2.4
A18: COMP | B18: Dadi | C18: 2 | D18: 3 | E18: =C18*D18 -> 6 | F18: 1.2 | G18: =E18*F18 -> 7.2
A19: COMP | B19: bulloni e tap pad INOX | C19: 2 | D19: 4 | E19: =C19*D19 -> 8 | F19: 1.3 | G19: =E19*F19 -> 10.4
A20: COMP | E20: =C20*D20 -> 0 | F20: 1.2 | G20: =E20*F20 -> 0
B21: Total | E21: =SUM(E16:E20) -> 17 | G21: =SUM(G16:G20) -> 21.2
A23: CDC | B23: Raw material | C23: Brut W. (Kg/pc) | D23: Net W. (Kg/pc) | E23: Scrap W. (Kg/pc) | F23: % Screp Value | G23: Transf. Price (€/Kg) | H23: Material Cost (€/pc) | I23: % Ric | J23: Price (€) | K23: LME ($/ton) | L23: Change (€/$) | M23: Material Cost (€/kg)
A24: CU | B24: LAM. CU ETP 1000x2000x3 H065 | C24: 0.22 | D24: 0.1 | E24: =C24-D24 -> 0.12 | F24: 0.7 | G24: 4.53 | H24: =IF($A24>0,(G24+M24)*C24-(K24/1000/L24*E24*F24),"") -> 2.3821843 | I24: 1 | J24: =IF($A24>0,H24*I24,"") -> 2.3821843 | K24: =IF($A24="CU",MP!$B$3,IF($A24="AL",MP!$I$3,"")) -> 9645.7 | L24: =IF($A24="CU",MP!$B$7,IF($A24="AL",MP!$I$7,"")) -> 1.1631 | M24: =IF($A24="CU",MP!$B$8,IF($A24="AL",MP!$I$8,"")) -> 9.4645651 | N24: Note mp
B25: Total | C25: =SUM(C24:C24) -> 0.22 | D25: =SUM(D24:D24) -> 0.1 | H25: =SUM(H24:H24) -> 2.3821843 | J25: =SUM(J24:J24) -> 2.3821843
A27: Fase | B27: Machining & Additional Operations | C27: Type | D27: Int/Ext | E27: Centro | F27: Cost (€/ora - €/pz) | G27: T. Setup (min) | H27: T. Prod (sec) | I27: Setup cost (€) | J27: Prod. cost (€) | K27: % Ric | L27: Setup Price | M27: Prod Price
A28: 1 | B28: Progettazione | C28: MACH | D28: I | E28: PRG | F28: 48 | G28: 30 | H28: 0 | I28: =IF(OR($L$4=0,$L$4=""),0,G28/60/$L$4*F28) -> 1.6 | J28: =IF(D28="I",F28/3600*H28,F28) -> 0 | K28: 1 | L28: =I28*K28 -> 1.6 | M28: =IF(C28="ADD",(J28 + I28)*K28,J28*K28) -> 0
A29: 10 | B29: Taglio Laser | C29: MACH | D29: I | E29: TL | F29: 150 | G29: 0 | H29: 20 | I29: =G29/60/$L$4*F29 -> 0 | J29: =IF(D29="I",F29/3600*H29,F29) -> 0.83333333 | K29: 1 | L29: =I29*K29 -> 0 | M29: =IF(C29="ADD",(J29 + I29)*K29,J29*K29) -> 0.83333333
A30: 20 | B30: Piega | C30: MACH | D30: I | E30: PIE | F30: 70 | G30: 30 | H30: 30 | I30: =G30/60/$L$4*F30 -> 2.3333333 | J30: =IF(D30="I",F30/3600*H30,F30) -> 0.58333333 | K30: 1 | L30: =I30*K30 -> 2.3333333 | M30: =IF(C30="ADD",(J30 + I30)*K30,J30*K30) -> 0.58333333
A31: 30 | B31: Satinatura | C31: MACH | D31: I | E31: SAT | F31: 70 | G31: 30 | H31: 30 | I31: =G31/60/$L$4*F31 -> 2.3333333 | J31: =IF(D31="I",F31/3600*H31,F31) -> 0.58333333 | K31: 1 | L31: =I31*K31 -> 2.3333333 | M31: =IF(C31="ADD",(J31 + I31)*K31,J31*K31) -> 0.58333333
A32: 40 | B32: Raggiatura Spigolo | C32: MACH | D32: I | E32: LAV | F32: 70 | G32: 0 | H32: 180 | I32: =G32/60/$L$4*F32 -> 0 | J32: =IF(D32="I",F32/3600*H32,F32) -> 3.5 | K32: 1 | L32: =I32*K32 -> 0 | M32: =IF(C32="ADD",(J32 + I32)*K32,J32*K32) -> 3.5
A33: 60 | B33: Insulation | C33: MACH | D33: I | E33: ISO | F33: 70 | G33: 0 | H33: 300 | I33: =G33/60/$L$4*F33 -> 0 | J33: =IF(D33="I",F33/3600*H33,F33) -> 5.8333333 | K33: 1.2 | L33: =I33*K33 -> 0 | M33: =IF(C33="ADD",(J33 + I33)*K33,J33*K33) -> 7
A34: 70 | B34: tinning 15µ | C34: ADD | D34: E | E34: TIN | F34: 1.1 | G34: 0 | H34: 0 | I34: =G34/60/$L$4*F34 -> 0 | J34: =IF(D34="I",F34/3600*H34,F34) -> 1.1 | K34: 1.2 | L34: =I34*K34 -> 0 | M34: =IF(C34="ADD",(J34 + I34)*K34,J34*K34) -> 1.32
A35: 80 | B35: Controllo finale | C35: MACH | D35: I | F35: 70 | G35: 0 | H35: 20 | I35: =G35/60/$L$4*F35 -> 0 | J35: =IF(D35="I",F35/3600*H35,F35) -> 0.38888889 | K35: 1 | L35: =I35*K35 -> 0 | M35: =IF(C35="ADD",(J35 + I35)*K35,J35*K35) -> 0.38888889
A36: 90 | C36: MACH | D36: I | K36: 1 | L36: =I36*K36 -> 0 | M36: =IF(C36="ADD",(J36 + I36)*K36,J36*K36) -> 0
A37: 100 | C37: MACH | D37: I | I37: =G37/60/$L$4*F37 -> 0 | J37: =IF(D37="I",F37/3600*H37,F37) -> 0 | K37: 1 | L37: =I37*K37 -> 0 | M37: =IF(C37="ADD",(J37 + I37)*K37,J37*K37) -> 0
B38: Total Machining | L38: =SUMIF(C28:C37,"MACH",L28:L37) -> 6.2666667 | M38: =SUMIF(C28:C37,"MACH",M28:M37) -> 12.888889
B39: Total Additional Operations | M39: =SUMIF(C28:C37,"ADD",M28:M37) -> 1.32
A41: Fase | B41: Treatments | C41: Type | D41: Int/Ext | E41: Centro | G41: Oper. Cost (€/pc) | H41: % Oper Ric | I41: Oper. Price (€) | J41: Q.ty Ag (gr) | K41: Silver cost (€) | L41: % Silver Ric | M41: Silver Price (€)
A42: 50 | B42: Argentatura | C42: ARG | D42: E | E42: Arg | G42: 4 | H42: 1.3 | I42: =G42*H42 -> 5.2 | J42: 10 | K42: =J42*MP!P3/1000 -> 11.0373 | L42: 1.1 | M42: =K42*L42 -> 12.14103
B43: Total | I43: =I42 -> 5.2 | M43: =M42 -> 12.14103
A45: CDC | B45: Altro | C45: Q.ty | D45: Unit Cost (€) | E45: Total cost (€) | G45: % Ric | H45: Price (€)
A46: TRAS | B46: Transport costs | C46: =D25 -> 0.1 | D46: 0.7 | E46: =C46*D46 -> 0.07 | G46: 1 | H46: =E46*G46 -> 0.07
...

Sheet SC3
B1: OFFER | G1: Nr. | H1: 01/25 | I1: Date: | J1: 44599 | K1: Rev.: | L1: 0
B2: Customer: | C2: SCHNEIDER | F2: Your request: | H2: 1234 / 25
B3: Doc. reference: | C3: AK00005841111 | F3: Description: | H3: Al bar model 3
B4: Drawing: | C4: AK00005841111 | F4: Rev.: | G4: A3 | H4: Quantity x year: | J4: 16 | K4: Pr.Batch: | L4: 16
B5: First delivery date: | C5: 45803 | E5: Last delivery date: | G5: 45950 | H5: Delivery Batch: | J5: 16
A7: CDC | B7: Tooling (Una tantum) | C7: Q.ty | D7: Cost (€) | E7: Total (€) | F7: % Ric | G7: Price (€) | N7: Note
A8: TOOL | B8: Attrezzo di piega | C8: 3 | D8: 1500 | E8: =C8*D8 -> 4500 | F8: 1.1 | G8: =E8*F8 -> 4950 | N8: Realizzazato internamente
A9: TOOL | B9: Attrezzo lav mec | C9: 3 | D9: 600 | E9: =C9*D9 -> 1800 | F9: 1.1 | G9: =E9*F9 -> 1980 | N9: Beretta
A10: TOOL | B10: Test di campionatura | C10: 3 | D10: 50 | E10: =C10*D10 -> 150 | F10: 1.1 | G10: =E10*F10 -> 165
A11: TOOL | E11: =C11*D11 -> 0 | F11: 1.1 | G11: =E11*F11 -> 0
A12: TOOL | E12: =C12*D12 -> 0 | F12: 1.1 | G12: =E12*F12 -> 0
B13: Total | E13: =SUM(E8:E12) -> 6450 | G13: =SUM(G8:G12) -> 7095
A15: CDC | B15: Components | C15: Q.ty | D15: Cost (€) | E15: Total Cost (€) | F15: % Ric | G15: Price (€)
A16: COMP | B16: Guaina | C16: 3 | D16: 0.5 | E16: =C16*D16 -> 1.5 | F16: 1.2 | G16: =E16*F16 -> 1.8
A17: COMP | B17: Rivetti | C17: 3 | D17: 1 | E17: =C17*D17 -> 3 | F17: 1.2 | G17: =E17*F17 -> 3.6
A18: COMP | B18: Dadi | C18: 3 | D18: 3 | E18: =C18*D18 -> 9 | F18: 1.2 | G18: =E18*F18 -> 10.8
A19: COMP | B19: bulloni e tap pad INOX | C19: 3 | D19: 4 | E19: =C19*D19 -> 12 | F19: 1.3 | G19: =E19*F19 -> 15.6
A20: COMP | E20: =C20*D20 -> 0 | F20: 1.2 | G20: =E20*F20 -> 0
B21: Total | E21: =SUM(E16:E20) -> 25.5 | G21: =SUM(G16:G20) -> 31.8
A23: CDC | B23: Raw material | C23: Brut W. (Kg/pc) | D23: Net W. (Kg/pc) | E23: Scrap W. (Kg/pc) | F23: % Screp Value | G23: Transf. Price (€/Kg) | H23: Material Cost (€/pc) | I23: % Ric | J23: Price (€) | K23: LME ($/ton) | L23: Change (€/$) | M23: Material Cost (€/kg)
A24: AL | B24: LAM. AL 1000x2000x3 H065 | C24: 2 | D24: 1 | E24: =C24-D24 -> 1 | F24: 0.7 | G24: 4.53 | H24: =IF($A24>0,(G24+M24)*C24-(K24/1000/L24*E24*F24),"") -> 11.959097 | I24: 1 | J24: =IF($A24>0,H24*I24,"") -> 11.959097 | K24: =IF($A24="CU",MP!$B$3,IF($A24="AL",MP!$I$3,"")) -> 2593.8 | L24: =IF($A24="CU",MP!$B$7,IF($A24="AL",MP!$I$7,"")) -> 1.1631 | M24: =IF($A24="CU",MP!$B$8,IF($A24="AL",MP!$I$8,"")) -> 2.2300748 | N24: Note mp
B25: Total | C25: =SUM(C24:C24) -> 2 | D25: =SUM(D24:D24) -> 1 | H25: =SUM(H24:H24) -> 11.959097 | J25: =SUM(J24:J24) -> 11.959097
A27: Fase | B27: Machining & Additional Operations | C27: Type | D27: Int/Ext | E27: Centro | F27: Cost (€/ora - €/pz) | G27: T. Setup (min) | H27: T. Prod (sec) | I27: Setup cost (€) | J27: Prod. cost (€) | K27: % Ric | L27: Setup Price | M27: Prod Price
A28: 1 | B28: Progettazione | C28: MACH | D28: I | E28: PRG | F28: 48 | G28: 30 | H28: 0 | I28: =IF(OR($L$4=0,$L$4=""),0,G28/60/$L$4*F28) -> 1.5 | J28: =IF(D28="I",F28/3600*H28,F28) -> 0 | K28: 1 | L28: =I28*K28 -> 1.5 | M28: =IF(C28="ADD",(J28 + I28)*K28,J28*K28) -> 0
A29: 10 | B29: Taglio Laser | C29: MACH | D29: I | E29: TL | F29: 150 | G29: 0 | H29: 20 | I29: =G29/60/$L$4*F29 -> 0 | J29: =IF(D29="I",F29/3600*H29,F29) -> 0.83333333 | K29: 1 | L29: =I29*K29 -> 0 | M29: =IF(C29="ADD",(J29 + I29)*K29,J29*K29) -> 0.83333333
A30: 20 | B30: Piega | C30: MACH | D30: I | E30: PIE | F30: 70 | G30: 60 | H30: 30 | I30: =G30/60/$L$4*F30 -> 4.375 | J30: =IF(D30="I",F30/3600*H30,F30) -> 0.58333333 | K30: 1 | L30: =I30*K30 -> 4.375 | M30: =IF(C30="ADD",(J30 + I30)*K30,J30*K30) -> 0.58333333
A31: 30 | B31: Satinatura | C31: MACH | D31: I | E31: SAT | F31: 70 | G31: 60 | H31: 30 | I31: =G31/60/$L$4*F31 -> 4.375 | J31: =IF(D31="I",F31/3600*H31,F31) -> 0.58333333 | K31: 1 | L31: =I31*K31 -> 4.375 | M31: =IF(C31="ADD",(J31 + I31)*K31,J31*K31) -> 0.58333333
A32: 40 | B32: Raggiatura Spigolo | C32: MACH | D32: I | E32: LAV | F32: 70 | G32: 0 | H32: 180 | I32: =G32/60/$L$4*F32 -> 0 | J32: =IF(D32="I",F32/3600*H32,F32) -> 3.5 | K32: 1 | L32: =I32*K32 -> 0 | M32: =IF(C32="ADD",(J32 + I32)*K32,J32*K32) -> 3.5
A33: 60 | B33: Insulation | C33: MACH | D33: I | E33: ISO | F33: 70 | G33: 0 | H33: 300 | I33: =G33/60/$L$4*F33 -> 0 | J33: =IF(D33="I",F33/3600*H33,F33) -> 5.8333333 | K33: 1.2 | L33: =I33*K33 -> 0 | M33: =IF(C33="ADD",(J33 + I33)*K33,J33*K33) -> 7
A34: 70 | B34: tinning 15µ | C34: ADD | D34: E | E34: TIN | F34: 1.1 | G34: 0 | H34: 0 | I34: =G34/60/$L$4*F34 -> 0 | J34: =IF(D34="I",F34/3600*H34,F34) -> 1.1 | K34: 1.2 | L34: =I34*K34 -> 0 | M34: =IF(C34="ADD",(J34 + I34)*K34,J34*K34) -> 1.32
A35: 80 | B35: Controllo finale | C35: MACH | D35: I | F35: 70 | G35: 0 | H35: 20 | I35: =G35/60/$L$4*F35 -> 0 | J35: =IF(D35="I",F35/3600*H35,F35) -> 0.38888889 | K35: 1 | L35: =I35*K35 -> 0 | M35: =IF(C35="ADD",(J35 + I35)*K35,J35*K35) -> 0.38888889
A36: 90 | C36: MACH | D36: I | K36: 1 | L36: =I36*K36 -> 0 | M36: =IF(C36="ADD",(J36 + I36)*K36,J36*K36) -> 0
A37: 100 | C37: MACH | D37: I | I37: =G37/60/$L$4*F37 -> 0 | J37: =IF(D37="I",F37/3600*H37,F37) -> 0 | K37: 1 | L37: =I37*K37 -> 0 | M37: =IF(C37="ADD",(J37 + I37)*K37,J37*K37) -> 0
B38: Total Machining | L38: =SUMIF(C28:C37,"MACH",L28:L37) -> 10.25 | M38: =SUMIF(C28:C37,"MACH",M28:M37) -> 12.888889
B39: Total Additional Operations | M39: =SUMIF(C28:C37,"ADD",M28:M37) -> 1.32
A41: Fase | B41: Treatments | C41: Type | D41: Int/Ext | E41: Centro | G41: Oper. Cost (€/pc) | H41: % Oper Ric | I41: Oper. Price (€) | J41: Q.ty Ag (gr) | K41: Silver cost (€) | L41: % Silver Ric | M41: Silver Price (€)
A42: 50 | B42: Argentatura | C42: ARG | D42: E | E42: Arg | G42: 4 | H42: 1.3 | I42: =G42*H42 -> 5.2 | J42: 20 | K42: =J42*MP!P3/1000 -> 22.0746 | L42: 1.1 | M42: =K42*L42 -> 24.28206
B43: Total | I43: =I42 -> 5.2 | M43: =M42 -> 24.28206
A45: CDC | B45: Altro | C45: Q.ty | D45: Unit Cost (€) | E45: Total cost (€) | G45: % Ric | H45: Price (€)
A46: TRAS | B46: Transport costs | C46: =D25 -> 1 | D46: 0.7 | E46: =C46*D46 -> 0.7 | G46: 1 | H46: =E46*G46 -> 0.7
...
